Workbook

Sheet Arbre
A1: Cascade des exigences : chaque exigence d'origine (bleu) ou décision (vert) avec les exigences dérivées qui en découlent
A2: Prio : M = MVP, S = V1 après MVP, V2 = hors V1. Vérif. : T = test automatique, M = test manuel sur téléphones, R = relecture. Les lignes dérivées se replient avec les boutons 1/2 en haut à gauche. Source des textes : onglet Exigences.
A4: Niveau | B4: ID | C4: Exigence | D4: Bloc | E4: Prio | F4: Vérif. | G4: Toutes les origines | H4: Nb dérivées
A5: Origine | B5: EX-A1 | C5: =INDEX(Exigences!$D:$D,MATCH(B5,Exigences!$A:$A,0)) | D5: =INDEX(Exigences!$C:$C,MATCH(B5,Exigences!$A:$A,0)) | H5: =INDEX(Exigences!$H:$H,MATCH(B5,Exigences!$A:$A,0))
A6: Dérivée | B6: D-A1-01 | C6: =INDEX(Exigences!$D:$D,MATCH(B6,Exigences!$A:$A,0)) | D6: =INDEX(Exigences!$C:$C,MATCH(B6,Exigences!$A:$A,0)) | E6: =INDEX(Exigences!$F:$F,MATCH(B6,Exigences!$A:$A,0)) | F6: =INDEX(Exigences!$G:$G,MATCH(B6,Exigences!$A:$A,0)) | G6: =INDEX(Exigences!$E:$E,MATCH(B6,Exigences!$A:$A,0))
A7: Dérivée | B7: D-A1-02 | C7: =INDEX(Exigences!$D:$D,MATCH(B7,Exigences!$A:$A,0)) | D7: =INDEX(Exigences!$C:$C,MATCH(B7,Exigences!$A:$A,0)) | E7: =INDEX(Exigences!$F:$F,MATCH(B7,Exigences!$A:$A,0)) | F7: =INDEX(Exigences!$G:$G,MATCH(B7,Exigences!$A:$A,0)) | G7: =INDEX(Exigences!$E:$E,MATCH(B7,Exigences!$A:$A,0))
A8: Dérivée | B8: D-A1-03 | C8: =INDEX(Exigences!$D:$D,MATCH(B8,Exigences!$A:$A,0)) | D8: =INDEX(Exigences!$C:$C,MATCH(B8,Exigences!$A:$A,0)) | E8: =INDEX(Exigences!$F:$F,MATCH(B8,Exigences!$A:$A,0)) | F8: =INDEX(Exigences!$G:$G,MATCH(B8,Exigences!$A:$A,0)) | G8: =INDEX(Exigences!$E:$E,MATCH(B8,Exigences!$A:$A,0))
A9: Dérivée | B9: D-A1-04 | C9: =INDEX(Exigences!$D:$D,MATCH(B9,Exigences!$A:$A,0)) | D9: =INDEX(Exigences!$C:$C,MATCH(B9,Exigences!$A:$A,0)) | E9: =INDEX(Exigences!$F:$F,MATCH(B9,Exigences!$A:$A,0)) | F9: =INDEX(Exigences!$G:$G,MATCH(B9,Exigences!$A:$A,0)) | G9: =INDEX(Exigences!$E:$E,MATCH(B9,Exigences!$A:$A,0))
A10: Dérivée | B10: D-A1-05 | C10: =INDEX(Exigences!$D:$D,MATCH(B10,Exigences!$A:$A,0)) | D10: =INDEX(Exigences!$C:$C,MATCH(B10,Exigences!$A:$A,0)) | E10: =INDEX(Exigences!$F:$F,MATCH(B10,Exigences!$A:$A,0)) | F10: =INDEX(Exigences!$G:$G,MATCH(B10,Exigences!$A:$A,0)) | G10: =INDEX(Exigences!$E:$E,MATCH(B10,Exigences!$A:$A,0))
A11: Dérivée | B11: D-A1-06 | C11: =INDEX(Exigences!$D:$D,MATCH(B11,Exigences!$A:$A,0)) | D11: =INDEX(Exigences!$C:$C,MATCH(B11,Exigences!$A:$A,0)) | E11: =INDEX(Exigences!$F:$F,MATCH(B11,Exigences!$A:$A,0)) | F11: =INDEX(Exigences!$G:$G,MATCH(B11,Exigences!$A:$A,0)) | G11: =INDEX(Exigences!$E:$E,MATCH(B11,Exigences!$A:$A,0))
A12: Dérivée | B12: D-A1-07 | C12: =INDEX(Exigences!$D:$D,MATCH(B12,Exigences!$A:$A,0)) | D12: =INDEX(Exigences!$C:$C,MATCH(B12,Exigences!$A:$A,0)) | E12: =INDEX(Exigences!$F:$F,MATCH(B12,Exigences!$A:$A,0)) | F12: =INDEX(Exigences!$G:$G,MATCH(B12,Exigences!$A:$A,0)) | G12: =INDEX(Exigences!$E:$E,MATCH(B12,Exigences!$A:$A,0))
A13: Dérivée | B13: D-A1-08 | C13: =INDEX(Exigences!$D:$D,MATCH(B13,Exigences!$A:$A,0)) | D13: =INDEX(Exigences!$C:$C,MATCH(B13,Exigences!$A:$A,0)) | E13: =INDEX(Exigences!$F:$F,MATCH(B13,Exigences!$A:$A,0)) | F13: =INDEX(Exigences!$G:$G,MATCH(B13,Exigences!$A:$A,0)) | G13: =INDEX(Exigences!$E:$E,MATCH(B13,Exigences!$A:$A,0))
A14: Dérivée | B14: D-A1-10 | C14: =INDEX(Exigences!$D:$D,MATCH(B14,Exigences!$A:$A,0)) | D14: =INDEX(Exigences!$C:$C,MATCH(B14,Exigences!$A:$A,0)) | E14: =INDEX(Exigences!$F:$F,MATCH(B14,Exigences!$A:$A,0)) | F14: =INDEX(Exigences!$G:$G,MATCH(B14,Exigences!$A:$A,0)) | G14: =INDEX(Exigences!$E:$E,MATCH(B14,Exigences!$A:$A,0))
A15: Dérivée | B15: D-A2-02 | C15: =INDEX(Exigences!$D:$D,MATCH(B15,Exigences!$A:$A,0)) | D15: =INDEX(Exigences!$C:$C,MATCH(B15,Exigences!$A:$A,0)) | E15: =INDEX(Exigences!$F:$F,MATCH(B15,Exigences!$A:$A,0)) | F15: =INDEX(Exigences!$G:$G,MATCH(B15,Exigences!$A:$A,0)) | G15: =INDEX(Exigences!$E:$E,MATCH(B15,Exigences!$A:$A,0))
A16: Dérivée | B16: D-A2-08 | C16: =INDEX(Exigences!$D:$D,MATCH(B16,Exigences!$A:$A,0)) | D16: =INDEX(Exigences!$C:$C,MATCH(B16,Exigences!$A:$A,0)) | E16: =INDEX(Exigences!$F:$F,MATCH(B16,Exigences!$A:$A,0)) | F16: =INDEX(Exigences!$G:$G,MATCH(B16,Exigences!$A:$A,0)) | G16: =INDEX(Exigences!$E:$E,MATCH(B16,Exigences!$A:$A,0))
A17: Dérivée | B17: D-A3-04 | C17: =INDEX(Exigences!$D:$D,MATCH(B17,Exigences!$A:$A,0)) | D17: =INDEX(Exigences!$C:$C,MATCH(B17,Exigences!$A:$A,0)) | E17: =INDEX(Exigences!$F:$F,MATCH(B17,Exigences!$A:$A,0)) | F17: =INDEX(Exigences!$G:$G,MATCH(B17,Exigences!$A:$A,0)) | G17: =INDEX(Exigences!$E:$E,MATCH(B17,Exigences!$A:$A,0))
... A19: Dérivée | B19: D-T-04 | C19: =INDEX(Exigences!$D:$D,MATCH(B19,Exigences!$A:$A,0)) | D19: =INDEX(Exigences!$C:$C,MATCH(B19,Exigences!$A:$A,0)) | E19: =INDEX(Exigences!$F:$F,MATCH(B19,Exigences!$A:$A,0)) | F19: =INDEX(Exigences!$G:$G,MATCH(B19,Exigences!$A:$A,0)) | G19: =INDEX(Exigences!$E:$E,MATCH(B19,Exigences!$A:$A,0))
A20: Origine | B20: EX-A2 | C20: =INDEX(Exigences!$D:$D,MATCH(B20,Exigences!$A:$A,0)) | D20: =INDEX(Exigences!$C:$C,MATCH(B20,Exigences!$A:$A,0)) | H20: =INDEX(Exigences!$H:$H,MATCH(B20,Exigences!$A:$A,0))
A21: Dérivée | B21: D-A2-01 | C21: =INDEX(Exigences!$D:$D,MATCH(B21,Exigences!$A:$A,0)) | D21: =INDEX(Exigences!$C:$C,MATCH(B21,Exigences!$A:$A,0)) | E21: =INDEX(Exigences!$F:$F,MATCH(B21,Exigences!$A:$A,0)) | F21: =INDEX(Exigences!$G:$G,MATCH(B21,Exigences!$A:$A,0)) | G21: =INDEX(Exigences!$E:$E,MATCH(B21,Exigences!$A:$A,0))
A22: Dérivée | B22: D-A3-03 | C22: =INDEX(Exigences!$D:$D,MATCH(B22,Exigences!$A:$A,0)) | D22: =INDEX(Exigences!$C:$C,MATCH(B22,Exigences!$A:$A,0)) | E22: =INDEX(Exigences!$F:$F,MATCH(B22,Exigences!$A:$A,0)) | F22: =INDEX(Exigences!$G:$G,MATCH(B22,Exigences!$A:$A,0)) | G22: =INDEX(Exigences!$E:$E,MATCH(B22,Exigences!$A:$A,0))
A23: Dérivée | B23: D-A3-04 | C23: =INDEX(Exigences!$D:$D,MATCH(B23,Exigences!$A:$A,0)) | D23: =INDEX(Exigences!$C:$C,MATCH(B23,Exigences!$A:$A,0)) | E23: =INDEX(Exigences!$F:$F,MATCH(B23,Exigences!$A:$A,0)) | F23: =INDEX(Exigences!$G:$G,MATCH(B23,Exigences!$A:$A,0)) | G23: =INDEX(Exigences!$E:$E,MATCH(B23,Exigences!$A:$A,0))
A24: Dérivée | B24: D-A3-11 | C24: =INDEX(Exigences!$D:$D,MATCH(B24,Exigences!$A:$A,0)) | D24: =INDEX(Exigences!$C:$C,MATCH(B24,Exigences!$A:$A,0)) | E24: =INDEX(Exigences!$F:$F,MATCH(B24,Exigences!$A:$A,0)) | F24: =INDEX(Exigences!$G:$G,MATCH(B24,Exigences!$A:$A,0)) | G24: =INDEX(Exigences!$E:$E,MATCH(B24,Exigences!$A:$A,0))
A25: Origine | B25: EX-A3 | C25: =INDEX(Exigences!$D:$D,MATCH(B25,Exigences!$A:$A,0)) | D25: =INDEX(Exigences!$C:$C,MATCH(B25,Exigences!$A:$A,0)) | H25: =INDEX(Exigences!$H:$H,MATCH(B25,Exigences!$A:$A,0))
A26: Dérivée | B26: D-A1-08 | C26: =INDEX(Exigences!$D:$D,MATCH(B26,Exigences!$A:$A,0)) | D26: =INDEX(Exigences!$C:$C,MATCH(B26,Exigences!$A:$A,0)) | E26: =INDEX(Exigences!$F:$F,MATCH(B26,Exigences!$A:$A,0)) | F26: =INDEX(Exigences!$G:$G,MATCH(B26,Exigences!$A:$A,0)) | G26: =INDEX(Exigences!$E:$E,MATCH(B26,Exigences!$A:$A,0))
A27: Dérivée | B27: D-A3-01 | C27: =INDEX(Exigences!$D:$D,MATCH(B27,Exigences!$A:$A,0)) | D27: =INDEX(Exigences!$C:$C,MATCH(B27,Exigences!$A:$A,0)) | E27: =INDEX(Exigences!$F:$F,MATCH(B27,Exigences!$A:$A,0)) | F27: =INDEX(Exigences!$G:$G,MATCH(B27,Exigences!$A:$A,0)) | G27: =INDEX(Exigences!$E:$E,MATCH(B27,Exigences!$A:$A,0))
A28: Dérivée | B28: D-A3-02 | C28: =INDEX(Exigences!$D:$D,MATCH(B28,Exigences!$A:$A,0)) | D28: =INDEX(Exigences!$C:$C,MATCH(B28,Exigences!$A:$A,0)) | E28: =INDEX(Exigences!$F:$F,MATCH(B28,Exigences!$A:$A,0)) | F28: =INDEX(Exigences!$G:$G,MATCH(B28,Exigences!$A:$A,0)) | G28: =INDEX(Exigences!$E:$E,MATCH(B28,Exigences!$A:$A,0))
A29: Dérivée | B29: D-A3-03 | C29: =INDEX(Exigences!$D:$D,MATCH(B29,Exigences!$A:$A,0)) | D29: =INDEX(Exigences!$C:$C,MATCH(B29,Exigences!$A:$A,0)) | E29: =INDEX(Exigences!$F:$F,MATCH(B29,Exigences!$A:$A,0)) | F29: =INDEX(Exigences!$G:$G,MATCH(B29,Exigences!$A:$A,0)) | G29: =INDEX(Exigences!$E:$E,MATCH(B29,Exigences!$A:$A,0))
A30: Dérivée | B30: D-A3-06 | C30: =INDEX(Exigences!$D:$D,MATCH(B30,Exigences!$A:$A,0)) | D30: =INDEX(Exigences!$C:$C,MATCH(B30,Exigences!$A:$A,0)) | E30: =INDEX(Exigences!$F:$F,MATCH(B30,Exigences!$A:$A,0)) | F30: =INDEX(Exigences!$G:$G,MATCH(B30,Exigences!$A:$A,0)) | G30: =INDEX(Exigences!$E:$E,MATCH(B30,Exigences!$A:$A,0))
A31: Dérivée | B31: D-A3-09 | C31: =INDEX(Exigences!$D:$D,MATCH(B31,Exigences!$A:$A,0)) | D31: =INDEX(Exigences!$C:$C,MATCH(B31,Exigences!$A:$A,0)) | E31: =INDEX(Exigences!$F:$F,MATCH(B31,Exigences!$A:$A,0)) | F31: =INDEX(Exigences!$G:$G,MATCH(B31,Exigences!$A:$A,0)) | G31: =INDEX(Exigences!$E:$E,MATCH(B31,Exigences!$A:$A,0))
A32: Dérivée | B32: D-A3-10 | C32: =INDEX(Exigences!$D:$D,MATCH(B32,Exigences!$A:$A,0)) | D32: =INDEX(Exigences!$C:$C,MATCH(B32,Exigences!$A:$A,0)) | E32: =INDEX(Exigences!$F:$F,MATCH(B32,Exigences!$A:$A,0)) | F32: =INDEX(Exigences!$G:$G,MATCH(B32,Exigences!$A:$A,0)) | G32: =INDEX(Exigences!$E:$E,MATCH(B32,Exigences!$A:$A,0))
A33: Dérivée | B33: D-A3-11 | C33: =INDEX(Exigences!$D:$D,MATCH(B33,Exigences!$A:$A,0)) | D33: =INDEX(Exigences!$C:$C,MATCH(B33,Exigences!$A:$A,0)) | E33: =INDEX(Exigences!$F:$F,MATCH(B33,Exigences!$A:$A,0)) | F33: =INDEX(Exigences!$G:$G,MATCH(B33,Exigences!$A:$A,0)) | G33: =INDEX(Exigences!$E:$E,MATCH(B33,Exigences!$A:$A,0))
A34: Dérivée | B34: D-A3-14 | C34: =INDEX(Exigences!$D:$D,MATCH(B34,Exigences!$A:$A,0)) | D34: =INDEX(Exigences!$C:$C,MATCH(B34,Exigences!$A:$A,0)) | E34: =INDEX(Exigences!$F:$F,MATCH(B34,Exigences!$A:$A,0)) | F34: =INDEX(Exigences!$G:$G,MATCH(B34,Exigences!$A:$A,0)) | G34: =INDEX(Exigences!$E:$E,MATCH(B34,Exigences!$A:$A,0))
A35: Dérivée | B35: D-T-03 | C35: =INDEX(Exigences!$D:$D,MATCH(B35,Exigences!$A:$A,0)) | D35: =INDEX(Exigences!$C:$C,MATCH(B35,Exigences!$A:$A,0)) | E35: =INDEX(Exigences!$F:$F,MATCH(B35,Exigences!$A:$A,0)) | F35: =INDEX(Exigences!$G:$G,MATCH(B35,Exigences!$A:$A,0)) | G35: =INDEX(Exigences!$E:$E,MATCH(B35,Exigences!$A:$A,0))
A36: Dérivée | B36: D-V2-02 | C36: =INDEX(Exigences!$D:$D,MATCH(B36,Exigences!$A:$A,0)) | D36: =INDEX(Exigences!$C:$C,MATCH(B36,Exigences!$A:$A,0)) | E36: =INDEX(Exigences!$F:$F,MATCH(B36,Exigences!$A:$A,0)) | F36: =INDEX(Exigences!$G:$G,MATCH(B36,Exigences!$A:$A,0)) | G36: =INDEX(Exigences!$E:$E,MATCH(B36,Exigences!$A:$A,0))
A37: Origine | B37: EX-B1 | C37: =INDEX(Exigences!$D:$D,MATCH(B37,Exigences!$A:$A,0)) | D37: =INDEX(Exigences!$C:$C,MATCH(B37,Exigences!$A:$A,0)) | H37: =INDEX(Exigences!$H:$H,MATCH(B37,Exigences!$A:$A,0))
A38: Dérivée | B38: D-A1-09 | C38: =INDEX(Exigences!$D:$D,MATCH(B38,Exigences!$A:$A,0)) | D38: =INDEX(Exigences!$C:$C,MATCH(B38,Exigences!$A:$A,0)) | E38: =INDEX(Exigences!$F:$F,MATCH(B38,Exigences!$A:$A,0)) | F38: =INDEX(Exigences!$G:$G,MATCH(B38,Exigences!$A:$A,0)) | G38: =INDEX(Exigences!$E:$E,MATCH(B38,Exigences!$A:$A,0))
A39: Dérivée | B39: D-B-01 | C39: =INDEX(Exigences!$D:$D,MATCH(B39,Exigences!$A:$A,0)) | D39: =INDEX(Exigences!$C:$C,MATCH(B39,Exigences!$A:$A,0)) | E39: =INDEX(Exigences!$F:$F,MATCH(B39,Exigences!$A:$A,0)) | F39: =INDEX(Exigences!$G:$G,MATCH(B39,Exigences!$A:$A,0)) | G39: =INDEX(Exigences!$E:$E,MATCH(B39,Exigences!$A:$A,0))
A40: Dérivée | B40: D-B-02 | C40: =INDEX(Exigences!$D:$D,MATCH(B40,Exigences!$A:$A,0)) | D40: =INDEX(Exigences!$C:$C,MATCH(B40,Exigences!$A:$A,0)) | E40: =INDEX(Exigences!$F:$F,MATCH(B40,Exigences!$A:$A,0)) | F40: =INDEX(Exigences!$G:$G,MATCH(B40,Exigences!$A:$A,0)) | G40: =INDEX(Exigences!$E:$E,MATCH(B40,Exigences!$A:$A,0))
A41: Origine | B41: EX-C1 | C41: =INDEX(Exigences!$D:$D,MATCH(B41,Exigences!$A:$A,0)) | D41: =INDEX(Exigences!$C:$C,MATCH(B41,Exigences!$A:$A,0)) | H41: =INDEX(Exigences!$H:$H,MATCH(B41,Exigences!$A:$A,0))
A42: Dérivée | B42: D-C-01 | C42: =INDEX(Exigences!$D:$D,MATCH(B42,Exigences!$A:$A,0)) | D42: =INDEX(Exigences!$C:$C,MATCH(B42,Exigences!$A:$A,0)) | E42: =INDEX(Exigences!$F:$F,MATCH(B42,Exigences!$A:$A,0)) | F42: =INDEX(Exigences!$G:$G,MATCH(B42,Exigences!$A:$A,0)) | G42: =INDEX(Exigences!$E:$E,MATCH(B42,Exigences!$A:$A,0))
...

Sheet Matrice
A1: Matrice de traçabilité : ● = l'exigence dérivée (ligne) découle de l'exigence d'origine ou de la décision (colonne)
A3: ID dérivée | B3: Bloc | C3: Exigence | D3: EX-A1 | E3: EX-A2 | F3: EX-A3 | G3: EX-B1 | H3: EX-C1 | I3: EX-C2 | J3: EX-C3 | K3: EX-D1 | L3: EX-D2 | M3: EX-E1 | N3: EX-E2 | O3: EX-E3 | P3: EX-E4 | Q3: DC-1 | R3: DC-2 | S3: DC-3 | T3: DC-4 | U3: DC-5 | V3: DC-6 | W3: DC-7 | X3: DC-8 | Y3: Nb origines
A4: D-A1-01 | B4: =INDEX(Exigences!$C:$C,MATCH(A4,Exigences!$A:$A,0)) | C4: =INDEX(Exigences!$D:$D,MATCH(A4,Exigences!$A:$A,0)) | D4: =IF(ISNUMBER(SEARCH(D$3,INDEX(Exigences!$E:$E,MATCH($A4,Exigences!$A:$A,0)))),"●","") | E4: =IF(ISNUMBER(SEARCH(E$3,INDEX(Exigences!$E:$E,MATCH($A4,Exigences!$A:$A,0)))),"●","") | F4: =IF(ISNUMBER(SEARCH(F$3,INDEX(Exigences!$E:$E,MATCH($A4,Exigences!$A:$A,0)))),"●","") | G4: =IF(ISNUMBER(SEARCH(G$3,INDEX(Exigences!$E:$E,MATCH($A4,Exigences!$A:$A,0)))),"●","") | H4: =IF(ISNUMBER(SEARCH(H$3,INDEX(Exigences!$E:$E,MATCH($A4,Exigences!$A:$A,0)))),"●","") | I4: =IF(ISNUMBER(SEARCH(I$3,INDEX(Exigences!$E:$E,MATCH($A4,Exigences!$A:$A,0)))),"●","") | J4: =IF(ISNUMBER(SEARCH(J$3,INDEX(Exigences!$E:$E,MATCH($A4,Exigences!$A:$A,0)))),"●","") | K4: =IF(ISNUMBER(SEARCH(K$3,INDEX(Exigences!$E:$E,MATCH($A4,Exigences!$A:$A,0)))),"●","") | ... X4: =IF(ISNUMBER(SEARCH(X$3,INDEX(Exigences!$E:$E,MATCH($A4,Exigences!$A:$A,0)))),"●","") | Y4: =COUNTIF(D4:X4,"●")
A5: D-A1-02 | B5: =INDEX(Exigences!$C:$C,MATCH(A5,Exigences!$A:$A,0)) | C5: =INDEX(Exigences!$D:$D,MATCH(A5,Exigences!$A:$A,0)) | D5: =IF(ISNUMBER(SEARCH(D$3,INDEX(Exigences!$E:$E,MATCH($A5,Exigences!$A:$A,0)))),"●","") | E5: =IF(ISNUMBER(SEARCH(E$3,INDEX(Exigences!$E:$E,MATCH($A5,Exigences!$A:$A,0)))),"●","") | F5: =IF(ISNUMBER(SEARCH(F$3,INDEX(Exigences!$E:$E,MATCH($A5,Exigences!$A:$A,0)))),"●","") | G5: =IF(ISNUMBER(SEARCH(G$3,INDEX(Exigences!$E:$E,MATCH($A5,Exigences!$A:$A,0)))),"●","") | H5: =IF(ISNUMBER(SEARCH(H$3,INDEX(Exigences!$E:$E,MATCH($A5,Exigences!$A:$A,0)))),"●","") | I5: =IF(ISNUMBER(SEARCH(I$3,INDEX(Exigences!$E:$E,MATCH($A5,Exigences!$A:$A,0)))),"●","") | J5: =IF(ISNUMBER(SEARCH(J$3,INDEX(Exigences!$E:$E,MATCH($A5,Exigences!$A:$A,0)))),"●","") | K5: =IF(ISNUMBER(SEARCH(K$3,INDEX(Exigences!$E:$E,MATCH($A5,Exigences!$A:$A,0)))),"●","") | ... X5: =IF(ISNUMBER(SEARCH(X$3,INDEX(Exigences!$E:$E,MATCH($A5,Exigences!$A:$A,0)))),"●","") | Y5: =COUNTIF(D5:X5,"●")
A6: D-A1-03 | B6: =INDEX(Exigences!$C:$C,MATCH(A6,Exigences!$A:$A,0)) | C6: =INDEX(Exigences!$D:$D,MATCH(A6,Exigences!$A:$A,0)) | D6: =IF(ISNUMBER(SEARCH(D$3,INDEX(Exigences!$E:$E,MATCH($A6,Exigences!$A:$A,0)))),"●","") | E6: =IF(ISNUMBER(SEARCH(E$3,INDEX(Exigences!$E:$E,MATCH($A6,Exigences!$A:$A,0)))),"●","") | F6: =IF(ISNUMBER(SEARCH(F$3,INDEX(Exigences!$E:$E,MATCH($A6,Exigences!$A:$A,0)))),"●","") | G6: =IF(ISNUMBER(SEARCH(G$3,INDEX(Exigences!$E:$E,MATCH($A6,Exigences!$A:$A,0)))),"●","") | H6: =IF(ISNUMBER(SEARCH(H$3,INDEX(Exigences!$E:$E,MATCH($A6,Exigences!$A:$A,0)))),"●","") | I6: =IF(ISNUMBER(SEARCH(I$3,INDEX(Exigences!$E:$E,MATCH($A6,Exigences!$A:$A,0)))),"●","") | J6: =IF(ISNUMBER(SEARCH(J$3,INDEX(Exigences!$E:$E,MATCH($A6,Exigences!$A:$A,0)))),"●","") | K6: =IF(ISNUMBER(SEARCH(K$3,INDEX(Exigences!$E:$E,MATCH($A6,Exigences!$A:$A,0)))),"●","") | ... X6: =IF(ISNUMBER(SEARCH(X$3,INDEX(Exigences!$E:$E,MATCH($A6,Exigences!$A:$A,0)))),"●","") | Y6: =COUNTIF(D6:X6,"●")
A7: D-A1-04 | B7: =INDEX(Exigences!$C:$C,MATCH(A7,Exigences!$A:$A,0)) | C7: =INDEX(Exigences!$D:$D,MATCH(A7,Exigences!$A:$A,0)) | D7: =IF(ISNUMBER(SEARCH(D$3,INDEX(Exigences!$E:$E,MATCH($A7,Exigences!$A:$A,0)))),"●","") | E7: =IF(ISNUMBER(SEARCH(E$3,INDEX(Exigences!$E:$E,MATCH($A7,Exigences!$A:$A,0)))),"●","") | F7: =IF(ISNUMBER(SEARCH(F$3,INDEX(Exigences!$E:$E,MATCH($A7,Exigences!$A:$A,0)))),"●","") | G7: =IF(ISNUMBER(SEARCH(G$3,INDEX(Exigences!$E:$E,MATCH($A7,Exigences!$A:$A,0)))),"●","") | H7: =IF(ISNUMBER(SEARCH(H$3,INDEX(Exigences!$E:$E,MATCH($A7,Exigences!$A:$A,0)))),"●","") | I7: =IF(ISNUMBER(SEARCH(I$3,INDEX(Exigences!$E:$E,MATCH($A7,Exigences!$A:$A,0)))),"●","") | J7: =IF(ISNUMBER(SEARCH(J$3,INDEX(Exigences!$E:$E,MATCH($A7,Exigences!$A:$A,0)))),"●","") | K7: =IF(ISNUMBER(SEARCH(K$3,INDEX(Exigences!$E:$E,MATCH($A7,Exigences!$A:$A,0)))),"●","") | ... X7: =IF(ISNUMBER(SEARCH(X$3,INDEX(Exigences!$E:$E,MATCH($A7,Exigences!$A:$A,0)))),"●","") | Y7: =COUNTIF(D7:X7,"●")
A8: D-A1-05 | B8: =INDEX(Exigences!$C:$C,MATCH(A8,Exigences!$A:$A,0)) | C8: =INDEX(Exigences!$D:$D,MATCH(A8,Exigences!$A:$A,0)) | D8: =IF(ISNUMBER(SEARCH(D$3,INDEX(Exigences!$E:$E,MATCH($A8,Exigences!$A:$A,0)))),"●","") | E8: =IF(ISNUMBER(SEARCH(E$3,INDEX(Exigences!$E:$E,MATCH($A8,Exigences!$A:$A,0)))),"●","") | F8: =IF(ISNUMBER(SEARCH(F$3,INDEX(Exigences!$E:$E,MATCH($A8,Exigences!$A:$A,0)))),"●","") | G8: =IF(ISNUMBER(SEARCH(G$3,INDEX(Exigences!$E:$E,MATCH($A8,Exigences!$A:$A,0)))),"●","") | H8: =IF(ISNUMBER(SEARCH(H$3,INDEX(Exigences!$E:$E,MATCH($A8,Exigences!$A:$A,0)))),"●","") | I8: =IF(ISNUMBER(SEARCH(I$3,INDEX(Exigences!$E:$E,MATCH($A8,Exigences!$A:$A,0)))),"●","") | J8: =IF(ISNUMBER(SEARCH(J$3,INDEX(Exigences!$E:$E,MATCH($A8,Exigences!$A:$A,0)))),"●","") | K8: =IF(ISNUMBER(SEARCH(K$3,INDEX(Exigences!$E:$E,MATCH($A8,Exigences!$A:$A,0)))),"●","") | ... X8: =IF(ISNUMBER(SEARCH(X$3,INDEX(Exigences!$E:$E,MATCH($A8,Exigences!$A:$A,0)))),"●","") | Y8: =COUNTIF(D8:X8,"●")
A9: D-A1-06 | B9: =INDEX(Exigences!$C:$C,MATCH(A9,Exigences!$A:$A,0)) | C9: =INDEX(Exigences!$D:$D,MATCH(A9,Exigences!$A:$A,0)) | D9: =IF(ISNUMBER(SEARCH(D$3,INDEX(Exigences!$E:$E,MATCH($A9,Exigences!$A:$A,0)))),"●","") | E9: =IF(ISNUMBER(SEARCH(E$3,INDEX(Exigences!$E:$E,MATCH($A9,Exigences!$A:$A,0)))),"●","") | F9: =IF(ISNUMBER(SEARCH(F$3,INDEX(Exigences!$E:$E,MATCH($A9,Exigences!$A:$A,0)))),"●","") | G9: =IF(ISNUMBER(SEARCH(G$3,INDEX(Exigences!$E:$E,MATCH($A9,Exigences!$A:$A,0)))),"●","") | H9: =IF(ISNUMBER(SEARCH(H$3,INDEX(Exigences!$E:$E,MATCH($A9,Exigences!$A:$A,0)))),"●","") | I9: =IF(ISNUMBER(SEARCH(I$3,INDEX(Exigences!$E:$E,MATCH($A9,Exigences!$A:$A,0)))),"●","") | J9: =IF(ISNUMBER(SEARCH(J$3,INDEX(Exigences!$E:$E,MATCH($A9,Exigences!$A:$A,0)))),"●","") | K9: =IF(ISNUMBER(SEARCH(K$3,INDEX(Exigences!$E:$E,MATCH($A9,Exigences!$A:$A,0)))),"●","") | ... X9: =IF(ISNUMBER(SEARCH(X$3,INDEX(Exigences!$E:$E,MATCH($A9,Exigences!$A:$A,0)))),"●","") | Y9: =COUNTIF(D9:X9,"●")
A10: D-A1-07 | B10: =INDEX(Exigences!$C:$C,MATCH(A10,Exigences!$A:$A,0)) | C10: =INDEX(Exigences!$D:$D,MATCH(A10,Exigences!$A:$A,0)) | D10: =IF(ISNUMBER(SEARCH(D$3,INDEX(Exigences!$E:$E,MATCH($A10,Exigences!$A:$A,0)))),"●","") | E10: =IF(ISNUMBER(SEARCH(E$3,INDEX(Exigences!$E:$E,MATCH($A10,Exigences!$A:$A,0)))),"●","") | F10: =IF(ISNUMBER(SEARCH(F$3,INDEX(Exigences!$E:$E,MATCH($A10,Exigences!$A:$A,0)))),"●","") | G10: =IF(ISNUMBER(SEARCH(G$3,INDEX(Exigences!$E:$E,MATCH($A10,Exigences!$A:$A,0)))),"●","") | H10: =IF(ISNUMBER(SEARCH(H$3,INDEX(Exigences!$E:$E,MATCH($A10,Exigences!$A:$A,0)))),"●","") | I10: =IF(ISNUMBER(SEARCH(I$3,INDEX(Exigences!$E:$E,MATCH($A10,Exigences!$A:$A,0)))),"●","") | J10: =IF(ISNUMBER(SEARCH(J$3,INDEX(Exigences!$E:$E,MATCH($A10,Exigences!$A:$A,0)))),"●","") | K10: =IF(ISNUMBER(SEARCH(K$3,INDEX(Exigences!$E:$E,MATCH($A10,Exigences!$A:$A,0)))),"●","") | ... X10: =IF(ISNUMBER(SEARCH(X$3,INDEX(Exigences!$E:$E,MATCH($A10,Exigences!$A:$A,0)))),"●","") | Y10: =COUNTIF(D10:X10,"●")
A11: D-A1-08 | B11: =INDEX(Exigences!$C:$C,MATCH(A11,Exigences!$A:$A,0)) | C11: =INDEX(Exigences!$D:$D,MATCH(A11,Exigences!$A:$A,0)) | D11: =IF(ISNUMBER(SEARCH(D$3,INDEX(Exigences!$E:$E,MATCH($A11,Exigences!$A:$A,0)))),"●","") | E11: =IF(ISNUMBER(SEARCH(E$3,INDEX(Exigences!$E:$E,MATCH($A11,Exigences!$A:$A,0)))),"●","") | F11: =IF(ISNUMBER(SEARCH(F$3,INDEX(Exigences!$E:$E,MATCH($A11,Exigences!$A:$A,0)))),"●","") | G11: =IF(ISNUMBER(SEARCH(G$3,INDEX(Exigences!$E:$E,MATCH($A11,Exigences!$A:$A,0)))),"●","") | H11: =IF(ISNUMBER(SEARCH(H$3,INDEX(Exigences!$E:$E,MATCH($A11,Exigences!$A:$A,0)))),"●","") | I11: =IF(ISNUMBER(SEARCH(I$3,INDEX(Exigences!$E:$E,MATCH($A11,Exigences!$A:$A,0)))),"●","") | J11: =IF(ISNUMBER(SEARCH(J$3,INDEX(Exigences!$E:$E,MATCH($A11,Exigences!$A:$A,0)))),"●","") | K11: =IF(ISNUMBER(SEARCH(K$3,INDEX(Exigences!$E:$E,MATCH($A11,Exigences!$A:$A,0)))),"●","") | ... X11: =IF(ISNUMBER(SEARCH(X$3,INDEX(Exigences!$E:$E,MATCH($A11,Exigences!$A:$A,0)))),"●","") | Y11: =COUNTIF(D11:X11,"●")
A12: D-A1-09 | B12: =INDEX(Exigences!$C:$C,MATCH(A12,Exigences!$A:$A,0)) | C12: =INDEX(Exigences!$D:$D,MATCH(A12,Exigences!$A:$A,0)) | D12: =IF(ISNUMBER(SEARCH(D$3,INDEX(Exigences!$E:$E,MATCH($A12,Exigences!$A:$A,0)))),"●","") | E12: =IF(ISNUMBER(SEARCH(E$3,INDEX(Exigences!$E:$E,MATCH($A12,Exigences!$A:$A,0)))),"●","") | F12: =IF(ISNUMBER(SEARCH(F$3,INDEX(Exigences!$E:$E,MATCH($A12,Exigences!$A:$A,0)))),"●","") | G12: =IF(ISNUMBER(SEARCH(G$3,INDEX(Exigences!$E:$E,MATCH($A12,Exigences!$A:$A,0)))),"●","") | H12: =IF(ISNUMBER(SEARCH(H$3,INDEX(Exigences!$E:$E,MATCH($A12,Exigences!$A:$A,0)))),"●","") | I12: =IF(ISNUMBER(SEARCH(I$3,INDEX(Exigences!$E:$E,MATCH($A12,Exigences!$A:$A,0)))),"●","") | J12: =IF(ISNUMBER(SEARCH(J$3,INDEX(Exigences!$E:$E,MATCH($A12,Exigences!$A:$A,0)))),"●","") | K12: =IF(ISNUMBER(SEARCH(K$3,INDEX(Exigences!$E:$E,MATCH($A12,Exigences!$A:$A,0)))),"●","") | ... X12: =IF(ISNUMBER(SEARCH(X$3,INDEX(Exigences!$E:$E,MATCH($A12,Exigences!$A:$A,0)))),"●","") | Y12: =COUNTIF(D12:X12,"●")
A13: D-A1-10 | B13: =INDEX(Exigences!$C:$C,MATCH(A13,Exigences!$A:$A,0)) | C13: =INDEX(Exigences!$D:$D,MATCH(A13,Exigences!$A:$A,0)) | D13: =IF(ISNUMBER(SEARCH(D$3,INDEX(Exigences!$E:$E,MATCH($A13,Exigences!$A:$A,0)))),"●","") | E13: =IF(ISNUMBER(SEARCH(E$3,INDEX(Exigences!$E:$E,MATCH($A13,Exigences!$A:$A,0)))),"●","") | F13: =IF(ISNUMBER(SEARCH(F$3,INDEX(Exigences!$E:$E,MATCH($A13,Exigences!$A:$A,0)))),"●","") | G13: =IF(ISNUMBER(SEARCH(G$3,INDEX(Exigences!$E:$E,MATCH($A13,Exigences!$A:$A,0)))),"●","") | H13: =IF(ISNUMBER(SEARCH(H$3,INDEX(Exigences!$E:$E,MATCH($A13,Exigences!$A:$A,0)))),"●","") | I13: =IF(ISNUMBER(SEARCH(I$3,INDEX(Exigences!$E:$E,MATCH($A13,Exigences!$A:$A,0)))),"●","") | J13: =IF(ISNUMBER(SEARCH(J$3,INDEX(Exigences!$E:$E,MATCH($A13,Exigences!$A:$A,0)))),"●","") | K13: =IF(ISNUMBER(SEARCH(K$3,INDEX(Exigences!$E:$E,MATCH($A13,Exigences!$A:$A,0)))),"●","") | ... X13: =IF(ISNUMBER(SEARCH(X$3,INDEX(Exigences!$E:$E,MATCH($A13,Exigences!$A:$A,0)))),"●","") | Y13: =COUNTIF(D13:X13,"●")
A14: D-A2-01 | B14: =INDEX(Exigences!$C:$C,MATCH(A14,Exigences!$A:$A,0)) | C14: =INDEX(Exigences!$D:$D,MATCH(A14,Exigences!$A:$A,0)) | D14: =IF(ISNUMBER(SEARCH(D$3,INDEX(Exigences!$E:$E,MATCH($A14,Exigences!$A:$A,0)))),"●","") | E14: =IF(ISNUMBER(SEARCH(E$3,INDEX(Exigences!$E:$E,MATCH($A14,Exigences!$A:$A,0)))),"●","") | F14: =IF(ISNUMBER(SEARCH(F$3,INDEX(Exigences!$E:$E,MATCH($A14,Exigences!$A:$A,0)))),"●","") | G14: =IF(ISNUMBER(SEARCH(G$3,INDEX(Exigences!$E:$E,MATCH($A14,Exigences!$A:$A,0)))),"●","") | H14: =IF(ISNUMBER(SEARCH(H$3,INDEX(Exigences!$E:$E,MATCH($A14,Exigences!$A:$A,0)))),"●","") | I14: =IF(ISNUMBER(SEARCH(I$3,INDEX(Exigences!$E:$E,MATCH($A14,Exigences!$A:$A,0)))),"●","") | J14: =IF(ISNUMBER(SEARCH(J$3,INDEX(Exigences!$E:$E,MATCH($A14,Exigences!$A:$A,0)))),"●","") | K14: =IF(ISNUMBER(SEARCH(K$3,INDEX(Exigences!$E:$E,MATCH($A14,Exigences!$A:$A,0)))),"●","") | ... X14: =IF(ISNUMBER(SEARCH(X$3,INDEX(Exigences!$E:$E,MATCH($A14,Exigences!$A:$A,0)))),"●","") | Y14: =COUNTIF(D14:X14,"●")
A15: D-A2-02 | B15: =INDEX(Exigences!$C:$C,MATCH(A15,Exigences!$A:$A,0)) | C15: =INDEX(Exigences!$D:$D,MATCH(A15,Exigences!$A:$A,0)) | D15: =IF(ISNUMBER(SEARCH(D$3,INDEX(Exigences!$E:$E,MATCH($A15,Exigences!$A:$A,0)))),"●","") | E15: =IF(ISNUMBER(SEARCH(E$3,INDEX(Exigences!$E:$E,MATCH($A15,Exigences!$A:$A,0)))),"●","") | F15: =IF(ISNUMBER(SEARCH(F$3,INDEX(Exigences!$E:$E,MATCH($A15,Exigences!$A:$A,0)))),"●","") | G15: =IF(ISNUMBER(SEARCH(G$3,INDEX(Exigences!$E:$E,MATCH($A15,Exigences!$A:$A,0)))),"●","") | H15: =IF(ISNUMBER(SEARCH(H$3,INDEX(Exigences!$E:$E,MATCH($A15,Exigences!$A:$A,0)))),"●","") | I15: =IF(ISNUMBER(SEARCH(I$3,INDEX(Exigences!$E:$E,MATCH($A15,Exigences!$A:$A,0)))),"●","") | J15: =IF(ISNUMBER(SEARCH(J$3,INDEX(Exigences!$E:$E,MATCH($A15,Exigences!$A:$A,0)))),"●","") | K15: =IF(ISNUMBER(SEARCH(K$3,INDEX(Exigences!$E:$E,MATCH($A15,Exigences!$A:$A,0)))),"●","") | ... X15: =IF(ISNUMBER(SEARCH(X$3,INDEX(Exigences!$E:$E,MATCH($A15,Exigences!$A:$A,0)))),"●","") | Y15: =COUNTIF(D15:X15,"●")
... A68: D-V2-07 | B68: =INDEX(Exigences!$C:$C,MATCH(A68,Exigences!$A:$A,0)) | C68: =INDEX(Exigences!$D:$D,MATCH(A68,Exigences!$A:$A,0)) | D68: =IF(ISNUMBER(SEARCH(D$3,INDEX(Exigences!$E:$E,MATCH($A68,Exigences!$A:$A,0)))),"●","") | E68: =IF(ISNUMBER(SEARCH(E$3,INDEX(Exigences!$E:$E,MATCH($A68,Exigences!$A:$A,0)))),"●","") | F68: =IF(ISNUMBER(SEARCH(F$3,INDEX(Exigences!$E:$E,MATCH($A68,Exigences!$A:$A,0)))),"●","") | G68: =IF(ISNUMBER(SEARCH(G$3,INDEX(Exigences!$E:$E,MATCH($A68,Exigences!$A:$A,0)))),"●","") | H68: =IF(ISNUMBER(SEARCH(H$3,INDEX(Exigences!$E:$E,MATCH($A68,Exigences!$A:$A,0)))),"●","") | I68: =IF(ISNUMBER(SEARCH(I$3,INDEX(Exigences!$E:$E,MATCH($A68,Exigences!$A:$A,0)))),"●","") | J68: =IF(ISNUMBER(SEARCH(J$3,INDEX(Exigences!$E:$E,MATCH($A68,Exigences!$A:$A,0)))),"●","") | K68: =IF(ISNUMBER(SEARCH(K$3,INDEX(Exigences!$E:$E,MATCH($A68,Exigences!$A:$A,0)))),"●","") | ... X68: =IF(ISNUMBER(SEARCH(X$3,INDEX(Exigences!$E:$E,MATCH($A68,Exigences!$A:$A,0)))),"●","") | Y68: =COUNTIF(D68:X68,"●")
A69: Nb dérivées | D69: =COUNTIF(D4:D68,"●") | E69: =COUNTIF(E4:E68,"●") | F69: =COUNTIF(F4:F68,"●") | G69: =COUNTIF(G4:G68,"●") | H69: =COUNTIF(H4:H68,"●") | I69: =COUNTIF(I4:I68,"●") | J69: =COUNTIF(J4:J68,"●") | K69: =COUNTIF(K4:K68,"●") | ... X69: =COUNTIF(X4:X68,"●") | Y69: =SUM(Y4:Y68)

Sheet Exigences
A1: ID | B1: Type | C1: Famille / bloc | D1: Exigence | E1: Origines (liens amont) | F1: Prio | G1: Vérif. | H1: Nb dérivées | I1: Statut
A2: EX-A1 | B2: Origine | C2: A | D2: Plusieurs jeux disponibles, avec possibilité d'en ajouter plus tard | H2: =COUNTIF($E$2:$E$200,"*"&A2&"*")
A3: EX-A2 | B3: Origine | C3: A | D3: Multijoueur jusqu'à 8 joueurs | H3: =COUNTIF($E$2:$E$200,"*"&A3&"*")
A4: EX-A3 | B4: Origine | C4: A | D4: Salons locaux façon DS, sans hébergement coûteux (gratuité) | H4: =COUNTIF($E$2:$E$200,"*"&A4&"*")
A5: EX-B1 | B5: Origine | C5: B | D5: Thème générique au début, graphismes à définir plus tard | H5: =COUNTIF($E$2:$E$200,"*"&A5&"*")
A6: EX-C1 | B6: Origine | C6: C | D6: Jeux de plateau (petits chevaux, Monopoly, échecs, dames...) | H6: =COUNTIF($E$2:$E$200,"*"&A6&"*")
A7: EX-C2 | B7: Origine | C7: C | D7: Jeux de cartes | H7: =COUNTIF($E$2:$E$200,"*"&A7&"*")
A8: EX-C3 | B8: Origine | C8: C | D8: Jouable sur n'importe quel téléphone | H8: =COUNTIF($E$2:$E$200,"*"&A8&"*")
A9: EX-D1 | B9: Origine | C9: D | D9: Aucun compte à créer | H9: =COUNTIF($E$2:$E$200,"*"&A9&"*")
A10: EX-D2 | B10: Origine | C10: D | D10: Gestion simplifiée : menu Jeux + menu Paramètres | H10: =COUNTIF($E$2:$E$200,"*"&A10&"*")
A11: EX-E1 | B11: Origine | C11: E | D11: Plus tard : jeux solo 2D variés (type Hollow Knight) | H11: =COUNTIF($E$2:$E$200,"*"&A11&"*")
A12: EX-E2 | B12: Origine | C12: E | D12: Plus tard : thèmes applicables aux jeux multi | H12: =COUNTIF($E$2:$E$200,"*"&A12&"*")
A13: EX-E3 | B13: Origine | C13: E | D13: Plus tard : serveur de comptes (contact, données bancaires) | H13: =COUNTIF($E$2:$E$200,"*"&A13&"*")
... A22: DC-8 | B22: Décision | C22: Cadrage | D22: Adresse github.io gratuite | H22: =COUNTIF($E$2:$E$200,"*"&A22&"*")
A23: D-A1-01 | B23: Dérivée | C23: Architecture | D23: PWA en TypeScript, jeux avec Phaser 3, menus HTML/CSS | E23: EX-A1, DC-1 | F23: M | G23: R | I23: Codé (PR #1), à vérifier avec les jeux ; à revoir en fin de dev
A24: D-A1-02 | B24: Dérivée | C24: Module de jeu | D24: Chaque jeu implémente une interface commune (contrat de jeu) | E24: EX-A1 | F24: M | G24: R | I24: Codé (PR #1), à vérifier avec les jeux
A25: D-A1-03 | B25: Dérivée | C25: Module de jeu | D25: Règles = fonctions pures, testées sans téléphone | E25: EX-A1 | F25: M | G25: T | I25: Codé (PR #1, Petits chevaux PR #4), à vérifier avec les jeux
A26: D-A1-04 | B26: Dérivée | C26: Registre des jeux | D26: Un registre liste les jeux ; le menu Jeux s'en construit | E26: EX-A1, EX-D2 | F26: M | G26: T | I26: Codé (PR #1), à vérifier avec les jeux
A27: D-A1-05 | B27: Dérivée | C27: Registre des jeux | D27: Ajouter un jeu = ajouter un dossier, sans toucher au noyau | E27: EX-A1 | F27: M | G27: R | I27: Codé (PR #1), à vérifier avec les jeux
A28: D-A1-06 | B28: Dérivée | C28: Session | D28: Mode un téléphone et mode réseau : même code de règles | E28: EX-A1, DC-2 | F28: M | G28: T | I28: Codé pour le mode un téléphone (PR #4) ; mode réseau à l'étape 3
A29: D-A1-07 | B29: Dérivée | C29: Module de jeu | D29: Hasard issu d'une graine, partie rejouable à l'identique | E29: EX-A1 | F29: M | G29: T | I29: Codé (PR #1, Petits chevaux PR #4), à vérifier avec les jeux
A30: D-A1-08 | B30: Dérivée | C30: Réseau WebRTC | D30: Versions du protocole et des jeux vérifiées à l'entrée du salon | E30: EX-A1, EX-A3 | F30: S | G30: T | I30: Codé (PR #3), à vérifier avec les jeux
A31: D-A1-09 | B31: Dérivée | C31: Écran et thème | D31: Images, sons et couleurs lus dans un pack de thème | E31: EX-B1, EX-E2 | F31: M | G31: R | I31: Codé pour Petits chevaux (PR #4), à vérifier avec les jeux
A32: D-A1-10 | B32: Dérivée | C32: Registre des jeux | D32: Le noyau ne connaît aucune règle de jeu | E32: EX-A1 | F32: M | G32: R | I32: Codé (PR #1), à vérifier avec les jeux
A33: D-A2-01 | B33: Dérivée | C33: Session | D33: Jusqu'à 8 joueurs (humains + ordinateurs) selon le jeu | E33: EX-A2 | F33: M | G33: T | I33: Codé (PR #1), à vérifier avec les jeux
A34: D-A2-02 | B34: Dérivée | C34: Session | D34: L'hôte valide chaque coup via le contrat | E34: EX-A1, EX-E4 | F34: M | G34: T | I34: Codé (PR #1), à vérifier avec les jeux
... A87: D-V2-07 | B87: Dérivée | C87: V2 | D87: Serveur de comptes : HTTPS, authentification, mises à jour | E87: EX-E4 | F87: V2 | G87: R | I87: À faire
